<?xml version="1.0"?>
<robot name="bipedal">

  <!-- core -->
  <link name="core">
   <visual>
     <geometry>
       <mesh filename="core.stl"/>
     </geometry>
     <origin rpy="0 0 0" xyz="0 0 -5"/>
   </visual>
   <collision>
     <geometry>
       <mesh filename="core.stl"/>
     </geometry>
     <origin rpy="0 0 0" xyz="0 0 0"/>
   </collision>
   <inertial>
     <mass value="10"/>
     <inertia ixx="1" iyy="1" izz="1"/>
   </inertial>
  </link>

  <!-- left leg -->

  <joint name="core_left_hip" type="revolute">
    <axis xyz="0 1 0"/>
    <limit effort="1000.0" lower="0.0" upper="3.14159" velocity="0.5"/>
    <parent link="core"/>
    <child link="left_hip"/>
    <origin xyz="3 0 0"/>
  </joint>

  <link name="left_hip">
    <visual>
      <geometry>
        <mesh filename="left_hip.stl"/>
      </geometry>
     <origin rpy="0 0 0" xyz="-3 0 -5"/>
    </visual>
    <collision>
      <geometry>
        <mesh filename="left_hip.stl"/>
      </geometry>
      <origin rpy="0 0 0" xyz="-3 0 -5"/>
    </collision>
    <inertial>
      <mass value="10"/>
      <inertia ixx="1" iyy="1" izz="1"/>
    </inertial>
  </link>

  <joint name="left_hip_left_leg_top" type="revolute">
    <axis xyz="1 0 0"/>
    <limit effort="1000.0" lower="0.0" upper="3.14159" velocity="0.5"/>
    <parent link="left_hip"/>
    <child link="left_leg_top"/>
    <origin xyz="0 0 0"/>
  </joint>

  <link name="left_leg_top">
    <visual>
      <geometry>
        <mesh filename="left_leg_top.stl"/>
      </geometry>
     <origin rpy="0 0 0" xyz="-3 0 -5"/>
    </visual>
    <collision>
      <geometry>
        <mesh filename="left_leg_top.stl"/>
      </geometry>
     <origin rpy="0 0 0" xyz="-3 0 -5"/>
    </collision>
    <inertial>
      <mass value="10"/>
      <inertia ixx="1" iyy="1" izz="1"/>
    </inertial>
  </link>

  <joint name="left_leg_top_left_leg_bottom" type="revolute">
    <axis xyz="1 0 0"/>
    <limit effort="1000.0" lower="0.0" upper="3.14159" velocity="0.5"/>
    <parent link="left_leg_top"/>
    <child link="left_leg_bottom"/>
    <origin xyz="0 0 -5"/>
  </joint>

  <link name="left_leg_bottom">
    <visual>
      <geometry>
        <mesh filename="left_leg_bottom.stl"/>
      </geometry>
     <origin rpy="0 0 0" xyz="-3 0 0"/>
    </visual>
    <collision>
      <geometry>
        <mesh filename="left_leg_bottom.stl"/>
      </geometry>
     <origin rpy="0 0 0" xyz="-3 0 0"/>
    </collision>
    <inertial>
      <mass value="10"/>
      <inertia ixx="1" iyy="1" izz="1"/>
    </inertial>
  </link>

  <!-- right leg -->

  <joint name="core_right_hip" type="revolute">
    <axis xyz="0 1 0"/>
    <limit effort="1000.0" lower="0.0" upper="3.14159" velocity="0.5"/>
    <parent link="core"/>
    <child link="right_hip"/>
    <origin xyz="-3 0 0"/>
  </joint>

 <link name="right_hip">
   <visual>
     <geometry>
       <mesh filename="right_hip.stl"/>
     </geometry>
     <origin rpy="0 0 0" xyz="3 0 -5"/>
   </visual>
   <collision>
     <geometry>
       <mesh filename="right_hip.stl"/>
     </geometry>
     <origin rpy="0 0 0" xyz="3 0 -5"/>
   </collision>
   <inertial>
     <mass value="10"/>
     <inertia ixx="1" iyy="1" izz="1"/>
   </inertial>
 </link>

 <joint name="right_hip_right_leg_top" type="revolute">
   <axis xyz="1 0 0"/>
   <limit effort="1000.0" lower="0.0" upper="3.14159" velocity="0.5"/>
   <parent link="right_hip"/>
   <child link="right_leg_top"/>
   <origin xyz="0 0 0"/>
 </joint>

 <link name="right_leg_top">
   <visual>
     <geometry>
       <mesh filename="right_leg_top.stl"/>
     </geometry>
    <origin rpy="0 0 0" xyz="3 0 -5"/>
   </visual>
   <collision>
     <geometry>
       <mesh filename="right_leg_top.stl"/>
     </geometry>
    <origin rpy="0 0 0" xyz="3 0 -5"/>
   </collision>
   <inertial>
     <mass value="10"/>
     <inertia ixx="1" iyy="1" izz="1"/>
   </inertial>
 </link>

 <joint name="right_leg_top_right_leg_bottom" type="revolute">
   <axis xyz="1 0 0"/>
   <limit effort="1000.0" lower="0.0" upper="3.14159" velocity="0.5"/>
   <parent link="right_leg_top"/>
   <child link="right_leg_bottom"/>
   <origin xyz="0 0 -5"/>
 </joint>

 <link name="right_leg_bottom">
   <visual>
     <geometry>
       <mesh filename="right_leg_bottom.stl"/>
     </geometry>
    <origin rpy="0 0 0" xyz="3 0 0"/>
   </visual>
   <collision>
     <geometry>
       <mesh filename="right_leg_bottom.stl"/>
     </geometry>
     <origin rpy="0 0 0" xyz="3 0 0"/>
   </collision>
   <inertial>
     <mass value="10"/>
     <inertia ixx="1" iyy="1" izz="1"/>
   </inertial>
 </link>


</robot>
